Start converting to h5
Traceback (most recent call last):
  File "/home/ubuntu/Documents/vt1code/voxceleb_trainer/SpeakerVerification/./dataprep.py", line 372, in <module>
    convert_to_h5(args)
  File "/home/ubuntu/Documents/vt1code/voxceleb_trainer/SpeakerVerification/./dataprep.py", line 285, in convert_to_h5
    f_dst.create_dataset("x", data=x_audio, compression="gzip", chunks=True, maxshape=(None,))
  File "/home/ubuntu/.local/lib/python3.10/site-packages/h5py/_hl/group.py", line 161, in create_dataset
    dsid = dataset.make_new_dset(group, shape, dtype, data, name, **kwds)
  File "/home/ubuntu/.local/lib/python3.10/site-packages/h5py/_hl/dataset.py", line 48, in make_new_dset
    data = base.array_for_new_object(data, specified_dtype=dtype)
  File "/home/ubuntu/.local/lib/python3.10/site-packages/h5py/_hl/base.py", line 118, in array_for_new_object
    data = np.asarray(data, order="C", dtype=as_dtype)
  File "h5py/_objects.pyx", line 54, in h5py._objects.with_phil.wrapper
  File "h5py/_objects.pyx", line 55, in h5py._objects.with_phil.wrapper
  File "/home/ubuntu/.local/lib/python3.10/site-packages/h5py/_hl/dataset.py", line 1040, in __array__
    arr = numpy.zeros(self.shape, dtype=self.dtype if dtype is None else dtype)
numpy.core._exceptions._ArrayMemoryError: Unable to allocate 506. GiB for an array with shape (135945777576,) and data type float32
